Workbook

Sheet Summary
A1: Post-Trade Reconciliation Report
A2: As-of business date 2026-10-07 | all values USD | synthetic demo data
A4: Headline | B4: Value
A5: Total break lines | B5: =COUNTA('All Breaks'!$A$2:$A$62)
A6: Root-cause breaks (excl. knock-on position/cash) | B6: =COUNTIF('All Breaks'!$C$2:$C$62,"<>*DRIVEN*")-(ROWS('All Breaks'!$A$2:$A$62)-COUNTA('All Breaks'!$A$2:$A$62))
A7: High-severity root-cause breaks | B7: =COUNTIFS('All Breaks'!$O$2:$O$62,"HIGH",'All Breaks'!$C$2:$C$62,"<>*DRIVEN*")
A8: Root-cause breaks older than 5 business days | B8: =COUNTIFS('All Breaks'!$M$2:$M$62,">5",'All Breaks'!$C$2:$C$62,"<>*DRIVEN*")
A9: Notional at risk, root-cause only (USD) | B9: =SUMIFS('All Breaks'!$K$2:$K$62,'All Breaks'!$C$2:$C$62,"<>*DRIVEN*")
A11: Owner team | B11: HIGH | C11: MEDIUM | D11: LOW | E11: Total | F11: Root-cause notional (USD)
A12: Trade Accounting & Operation | B12: =COUNTIFS('All Breaks'!$D$2:$D$62,$A12,'All Breaks'!$O$2:$O$62,"HIGH") | C12: =COUNTIFS('All Breaks'!$D$2:$D$62,$A12,'All Breaks'!$O$2:$O$62,"MEDIUM") | D12: =COUNTIFS('All Breaks'!$D$2:$D$62,$A12,'All Breaks'!$O$2:$O$62,"LOW") | E12: =SUM(B12:D12) | F12: =SUMIFS('All Breaks'!$K$2:$K$62,'All Breaks'!$D$2:$D$62,$A12,'All Breaks'!$C$2:$C$62,"<>*DRIVEN*")
A13: Middle Office | B13: =COUNTIFS('All Breaks'!$D$2:$D$62,$A13,'All Breaks'!$O$2:$O$62,"HIGH") | C13: =COUNTIFS('All Breaks'!$D$2:$D$62,$A13,'All Breaks'!$O$2:$O$62,"MEDIUM") | D13: =COUNTIFS('All Breaks'!$D$2:$D$62,$A13,'All Breaks'!$O$2:$O$62,"LOW") | E13: =SUM(B13:D13) | F13: =SUMIFS('All Breaks'!$K$2:$K$62,'All Breaks'!$D$2:$D$62,$A13,'All Breaks'!$C$2:$C$62,"<>*DRIVEN*")
A14: Treasury | B14: =COUNTIFS('All Breaks'!$D$2:$D$62,$A14,'All Breaks'!$O$2:$O$62,"HIGH") | C14: =COUNTIFS('All Breaks'!$D$2:$D$62,$A14,'All Breaks'!$O$2:$O$62,"MEDIUM") | D14: =COUNTIFS('All Breaks'!$D$2:$D$62,$A14,'All Breaks'!$O$2:$O$62,"LOW") | E14: =SUM(B14:D14) | F14: =SUMIFS('All Breaks'!$K$2:$K$62,'All Breaks'!$D$2:$D$62,$A14,'All Breaks'!$C$2:$C$62,"<>*DRIVEN*")
A15: Pricing | B15: =COUNTIFS('All Breaks'!$D$2:$D$62,$A15,'All Breaks'!$O$2:$O$62,"HIGH") | C15: =COUNTIFS('All Breaks'!$D$2:$D$62,$A15,'All Breaks'!$O$2:$O$62,"MEDIUM") | D15: =COUNTIFS('All Breaks'!$D$2:$D$62,$A15,'All Breaks'!$O$2:$O$62,"LOW") | E15: =SUM(B15:D15) | F15: =SUMIFS('All Breaks'!$K$2:$K$62,'All Breaks'!$D$2:$D$62,$A15,'All Breaks'!$C$2:$C$62,"<>*DRIVEN*")
A16: Total | B16: =SUM(B12:B15) | C16: =SUM(C12:C15) | D16: =SUM(D12:D15) | E16: =SUM(E12:E15) | F16: =SUM(F12:F15)
A19: Reconciliation | B19: Items compared | C19: Items with breaks | D19: Items matched | E19: Match rate
A20: Trade | B20: 304 | C20: 31 | D20: 273 | E20: 0.898
A21: Position | B21: 72 | C21: 19 | D21: 53 | E21: 0.7361
A22: Cash | B22: 3 | C22: 3 | D22: 0 | E22: 0
A23: Margin | B23: 11 | C23: 3 | D23: 8 | E23: 0.7273
A24: Pricing | B24: 24 | C24: 5 | D24: 19 | E24: 0.7917
A27: Break type | B27: Count | C27: Notional (USD)
A28: CASH_BREAK_UNEXPLAINED_RESIDUAL | B28: =COUNTIF('All Breaks'!$C$2:$C$62,$A28) | C28: =SUMIFS('All Breaks'!$K$2:$K$62,'All Breaks'!$C$2:$C$62,$A28)
A29: CASH_BREAK_UPSTREAM_DRIVEN | B29: =COUNTIF('All Breaks'!$C$2:$C$62,$A29) | C29: =SUMIFS('All Breaks'!$K$2:$K$62,'All Breaks'!$C$2:$C$62,$A29)
A30: MARGIN_AMOUNT_MISMATCH | B30: =COUNTIF('All Breaks'!$C$2:$C$62,$A30) | C30: =SUMIFS('All Breaks'!$K$2:$K$62,'All Breaks'!$C$2:$C$62,$A30)
A31: MARGIN_MISSING_IN_CUSTODIAN | B31: =COUNTIF('All Breaks'!$C$2:$C$62,$A31) | C31: =SUMIFS('All Breaks'!$K$2:$K$62,'All Breaks'!$C$2:$C$62,$A31)
A32: MARGIN_MISSING_IN_INTERNAL | B32: =COUNTIF('All Breaks'!$C$2:$C$62,$A32) | C32: =SUMIFS('All Breaks'!$K$2:$K$62,'All Breaks'!$C$2:$C$62,$A32)
A33: POSITION_BREAK_CORP_ACTION_SPLIT | B33: =COUNTIF('All Breaks'!$C$2:$C$62,$A33) | C33: =SUMIFS('All Breaks'!$K$2:$K$62,'All Breaks'!$C$2:$C$62,$A33)
A34: POSITION_BREAK_TRADE_DRIVEN | B34: =COUNTIF('All Breaks'!$C$2:$C$62,$A34) | C34: =SUMIFS('All Breaks'!$K$2:$K$62,'All Breaks'!$C$2:$C$62,$A34)
A35: PRICING_STALE | B35: =COUNTIF('All Breaks'!$C$2:$C$62,$A35) | C35: =SUMIFS('All Breaks'!$K$2:$K$62,'All Breaks'!$C$2:$C$62,$A35)
A36: PRICING_VARIANCE | B36: =COUNTIF('All Breaks'!$C$2:$C$62,$A36) | C36: =SUMIFS('All Breaks'!$K$2:$K$62,'All Breaks'!$C$2:$C$62,$A36)
A37: TRADE_MISSING_IN_CUSTODIAN | B37: =COUNTIF('All Breaks'!$C$2:$C$62,$A37) | C37: =SUMIFS('All Breaks'!$K$2:$K$62,'All Breaks'!$C$2:$C$62,$A37)
A38: TRADE_MISSING_IN_INTERNAL | B38: =COUNTIF('All Breaks'!$C$2:$C$62,$A38) | C38: =SUMIFS('All Breaks'!$K$2:$K$62,'All Breaks'!$C$2:$C$62,$A38)
A39: TRADE_PRICE_MISMATCH | B39: =COUNTIF('All Breaks'!$C$2:$C$62,$A39) | C39: =SUMIFS('All Breaks'!$K$2:$K$62,'All Breaks'!$C$2:$C$62,$A39)
... A41: TRADE_SETTLE_DATE_MISMATCH | B41: =COUNTIF('All Breaks'!$C$2:$C$62,$A41) | C41: =SUMIFS('All Breaks'!$K$2:$K$62,'All Breaks'!$C$2:$C$62,$A41)

Sheet Ageing
A1: Ageing of open breaks (business days)
A2: Counts update when 'All Breaks' is filtered or edited
A4: Owner team | B4: 0-1d | C4: 2-5d | D4: 6-10d | E4: 11+d | F4: Total
A5: Trade Accounting & Operation | B5: =COUNTIFS('All Breaks'!$D$2:$D$62,$A5,'All Breaks'!$N$2:$N$62,"="&B$4) | C5: =COUNTIFS('All Breaks'!$D$2:$D$62,$A5,'All Breaks'!$N$2:$N$62,"="&C$4) | D5: =COUNTIFS('All Breaks'!$D$2:$D$62,$A5,'All Breaks'!$N$2:$N$62,"="&D$4) | E5: =COUNTIFS('All Breaks'!$D$2:$D$62,$A5,'All Breaks'!$N$2:$N$62,"="&E$4) | F5: =SUM(B5:E5)
A6: Middle Office | B6: =COUNTIFS('All Breaks'!$D$2:$D$62,$A6,'All Breaks'!$N$2:$N$62,"="&B$4) | C6: =COUNTIFS('All Breaks'!$D$2:$D$62,$A6,'All Breaks'!$N$2:$N$62,"="&C$4) | D6: =COUNTIFS('All Breaks'!$D$2:$D$62,$A6,'All Breaks'!$N$2:$N$62,"="&D$4) | E6: =COUNTIFS('All Breaks'!$D$2:$D$62,$A6,'All Breaks'!$N$2:$N$62,"="&E$4) | F6: =SUM(B6:E6)
A7: Treasury | B7: =COUNTIFS('All Breaks'!$D$2:$D$62,$A7,'All Breaks'!$N$2:$N$62,"="&B$4) | C7: =COUNTIFS('All Breaks'!$D$2:$D$62,$A7,'All Breaks'!$N$2:$N$62,"="&C$4) | D7: =COUNTIFS('All Breaks'!$D$2:$D$62,$A7,'All Breaks'!$N$2:$N$62,"="&D$4) | E7: =COUNTIFS('All Breaks'!$D$2:$D$62,$A7,'All Breaks'!$N$2:$N$62,"="&E$4) | F7: =SUM(B7:E7)
A8: Pricing | B8: =COUNTIFS('All Breaks'!$D$2:$D$62,$A8,'All Breaks'!$N$2:$N$62,"="&B$4) | C8: =COUNTIFS('All Breaks'!$D$2:$D$62,$A8,'All Breaks'!$N$2:$N$62,"="&C$4) | D8: =COUNTIFS('All Breaks'!$D$2:$D$62,$A8,'All Breaks'!$N$2:$N$62,"="&D$4) | E8: =COUNTIFS('All Breaks'!$D$2:$D$62,$A8,'All Breaks'!$N$2:$N$62,"="&E$4) | F8: =SUM(B8:E8)

Sheet All Breaks
A1: Break Id | B1: Category | C1: Break Type | D1: Owner Team | E1: Account | F1: Security Id | G1: Reference | H1: Internal Value | I1: Custodian Value | J1: Difference | K1: Notional Usd | L1: Reference Date | M1: Age Days | N1: Age Bucket | O1: Severity | P1: Explanation | Q1: Suggested Action
A2: BRK-20261007-0001 | B2: POSITION | C2: POSITION_BREAK_CORP_ACTION_SPLIT | D2: Middle Office | E2: FUND_GAMMA | F2: SEC009 | G2: FUND_GAMMA|SEC009 | H2: 37000 | I2: 74000 | J2: -37000 | K2: 12218536 | L2: 46302 | M2: 0 | N2: 0-1d | O2: HIGH | P2: Custodian quantity is exactly 2x the platform: 2-for-1 split not booked on the platform. | Q2: Book the split on the platform (ratio and ex-date) and re-run.
A3: BRK-20261007-0002 | B3: POSITION | C3: POSITION_BREAK_CORP_ACTION_SPLIT | D3: Middle Office | E3: FUND_ALPHA | F3: SEC009 | G3: FUND_ALPHA|SEC009 | H3: 31600 | I3: 63200 | J3: -31600 | K3: 10435290 | L3: 46302 | M3: 0 | N3: 0-1d | O3: HIGH | P3: Custodian quantity is exactly 2x the platform: 2-for-1 split not booked on the platform. | Q3: Book the split on the platform (ratio and ex-date) and re-run.
A4: BRK-20261007-0003 | B4: POSITION | C4: POSITION_BREAK_CORP_ACTION_SPLIT | D4: Middle Office | E4: FUND_BETA | F4: SEC009 | G4: FUND_BETA|SEC009 | H4: -25600 | I4: -51200 | J4: 25600 | K4: 8453905.9 | L4: 46302 | M4: 0 | N4: 0-1d | O4: HIGH | P4: Custodian quantity is exactly 2x the platform: 2-for-1 split not booked on the platform. | Q4: Book the split on the platform (ratio and ex-date) and re-run.
A5: BRK-20261007-0004 | B5: POSITION | C5: POSITION_BREAK_CORP_ACTION_SPLIT | D5: Middle Office | E5: FUND_GAMMA | F5: SEC004 | G5: FUND_GAMMA|SEC004 | H5: 33000 | I5: 66000 | J5: -33000 | K5: 8160814.2 | L5: 46302 | M5: 0 | N5: 0-1d | O5: HIGH | P5: Custodian quantity is exactly 2x the platform: 2-for-1 split not booked on the platform. | Q5: Book the split on the platform (ratio and ex-date) and re-run.
A6: BRK-20261007-0005 | B6: POSITION | C6: POSITION_BREAK_CORP_ACTION_SPLIT | D6: Middle Office | E6: FUND_ALPHA | F6: SEC004 | G6: FUND_ALPHA|SEC004 | H6: 28900 | I6: 57800 | J6: -28900 | K6: 7146894.9 | L6: 46302 | M6: 0 | N6: 0-1d | O6: HIGH | P6: Custodian quantity is exactly 2x the platform: 2-for-1 split not booked on the platform. | Q6: Book the split on the platform (ratio and ex-date) and re-run.
A7: BRK-20261007-0006 | B7: POSITION | C7: POSITION_BREAK_CORP_ACTION_SPLIT | D7: Middle Office | E7: FUND_BETA | F7: SEC004 | G7: FUND_BETA|SEC004 | H7: -26700 | I7: -53400 | J7: 26700 | K7: 6602840.6 | L7: 46302 | M7: 0 | N7: 0-1d | O7: HIGH | P7: Custodian quantity is exactly 2x the platform: 2-for-1 split not booked on the platform. | Q7: Book the split on the platform (ratio and ex-date) and re-run.
A8: BRK-20261007-0007 | B8: TRADE | C8: TRADE_SETTLE_DATE_MISMATCH | D8: Trade Accounting & Operation | E8: FUND_ALPHA | F8: SEC012 | G8: TRD100187 | H8: 2026-10-06 | I8: 2026-10-07 | K8: 4821861.5 | L8: 46301 | M8: 1 | N8: 0-1d | O8: HIGH | P8: Settlement dates disagree; risk of a settlement fail. | Q8: Check SSI and settlement instructions; align settle date to avoid a fail.
A9: BRK-20261007-0008 | B9: TRADE | C9: TRADE_MISSING_IN_CUSTODIAN | D9: Trade Accounting & Operation | E9: FUND_ALPHA | F9: SEC011 | G9: TRD100267 | H9: SELL 11,800 @ 391.9323 | I9: (missing) | K9: 4624801.1 | L9: 46300 | M9: 2 | N9: 2-5d | O9: HIGH | P9: Trade exists on the platform but not at the custodian. | Q9: Confirm trade with counterparty; check allocation and send trade to custodian.
A10: BRK-20261007-0009 | B10: TRADE | C10: TRADE_SETTLE_DATE_MISMATCH | D10: Trade Accounting & Operation | E10: FUND_BETA | F10: SEC012 | G10: TRD100046 | H10: 2026-10-06 | I10: 2026-10-07 | K10: 3714541 | L10: 46301 | M10: 1 | N10: 0-1d | O10: HIGH | P10: Settlement dates disagree; risk of a settlement fail. | Q10: Check SSI and settlement instructions; align settle date to avoid a fail.
A11: BRK-20261007-0010 | B11: POSITION | C11: POSITION_BREAK_TRADE_DRIVEN | D11: Trade Accounting & Operation | E11: FUND_ALPHA | F11: SEC011 | G11: FUND_ALPHA|SEC011 | H11: 39600 | I11: 47600 | J11: -8000 | K11: 3135335.2 | L11: 46302 | M11: 0 | N11: 0-1d | O11: HIGH | P11: Fully explained by trade break(s): TRD100089, TRD100267, TRD90001 | Q11: No separate action; clears when the linked trade break is resolved.
A12: BRK-20261007-0011 | B12: TRADE | C12: TRADE_MISSING_IN_CUSTODIAN | D12: Trade Accounting & Operation | E12: FUND_BETA | F12: SEC015 | G12: TRD100164 | H12: BUY 13,500 @ 216.9081 | I12: (missing) | K12: 2928259.4 | L12: 46290 | M12: 8 | N12: 6-10d | O12: HIGH | P12: Trade exists on the platform but not at the custodian. | Q12: Confirm trade with counterparty; check allocation and send trade to custodian.
A13: BRK-20261007-0012 | B13: POSITION | C13: POSITION_BREAK_TRADE_DRIVEN | D13: Trade Accounting & Operation | E13: FUND_BETA | F13: SEC015 | G13: FUND_BETA|SEC015 | H13: 14500 | I13: 1000 | J13: 13500 | K13: 2916110.7 | L13: 46302 | M13: 0 | N13: 0-1d | O13: HIGH | P13: Fully explained by trade break(s): TRD100164 | Q13: No separate action; clears when the linked trade break is resolved.
A14: BRK-20261007-0013 | B14: POSITION | C14: POSITION_BREAK_TRADE_DRIVEN | D14: Trade Accounting & Operation | E14: FUND_BETA | F14: SEC018 | G14: FUND_BETA|SEC018 | H14: -300 | I14: -13000 | J14: 12700 | K14: 2870954.4 | L14: 46302 | M14: 0 | N14: 0-1d | O14: HIGH | P14: Fully explained by trade break(s): TRD100292 | Q14: No separate action; clears when the linked trade break is resolved.
A15: BRK-20261007-0014 | B15: TRADE | C15: TRADE_MISSING_IN_CUSTODIAN | D15: Trade Accounting & Operation | E15: FUND_BETA | F15: SEC018 | G15: TRD100292 | H15: BUY 12,700 @ 224.9186 | I15: (missing) | K15: 2856466.2 | L15: 46296 | M15: 4 | N15: 2-5d | O15: HIGH | P15: Trade exists on the platform but not at the custodian. | Q15: Confirm trade with counterparty; check allocation and send trade to custodian.
A16: BRK-20261007-0015 | B16: TRADE | C16: TRADE_SETTLE_DATE_MISMATCH | D16: Trade Accounting & Operation | E16: FUND_GAMMA | F16: SEC007 | G16: TRD100091 | H16: 2026-09-25 | I16: 2026-09-28 | K16: 2070628.4 | L16: 46290 | M16: 8 | N16: 6-10d | O16: HIGH | P16: Settlement dates disagree; risk of a settlement fail. | Q16: Check SSI and settlement instructions; align settle date to avoid a fail.
A17: BRK-20261007-0016 | B17: CASH | C17: CASH_BREAK_UPSTREAM_DRIVEN | D17: Trade Accounting & Operation | E17: FUND_ALPHA | G17: FUND_ALPHA|USD | H17: -12494368 | I17: -14468854 | J17: 1974486.1 | K17: 1974486.1 | L17: 46302 | M17: 0 | N17: 0-1d | O17: HIGH | P17: Fully explained by: trade breaks 1,976,331.08; margin breaks 0.00; unbooked dividends -1,845.00; residual 0.00 | Q17: No separate action; clears when linked trade, margin and corporate action breaks clear.
A18: BRK-20261007-0017 | B18: POSITION | C18: POSITION_BREAK_TRADE_DRIVEN | D18: Trade Accounting & Operation | E18: FUND_ALPHA | F18: SEC008 | G18: FUND_ALPHA|SEC008 | H18: 22800 | I18: 3300 | J18: 19500 | K18: 1502987.9 | L18: 46302 | M18: 0 | N18: 0-1d | O18: HIGH | P18: Fully explained by trade break(s): TRD100027 | Q18: No separate action; clears when the linked trade break is resolved.
A19: BRK-20261007-0018 | B19: TRADE | C19: TRADE_MISSING_IN_CUSTODIAN | D19: Trade Accounting & Operation | E19: FUND_ALPHA | F19: SEC008 | G19: TRD100027 | H19: BUY 19,500 @ 76.9914 | I19: (missing) | K19: 1501332.3 | L19: 46289 | M19: 9 | N19: 6-10d | O19: HIGH | P19: Trade exists on the platform but not at the custodian. | Q19: Confirm trade with counterparty; check allocation and send trade to custodian.
A20: BRK-20261007-0019 | B20: TRADE | C20: TRADE_MISSING_IN_INTERNAL | D20: Trade Accounting & Operation | E20: FUND_ALPHA | F20: SEC011 | G20: TRD90001 | H20: (missing) | I20: SELL 3,800 @ 391.9242 | K20: 1489312 | L20: 46288 | M20: 10 | N20: 6-10d | O20: HIGH | P20: Trade exists at the custodian but not on the platform. | Q20: Check for unbooked trade or wrong account; book trade or reject with custodian.
A21: BRK-20261007-0020 | B21: TRADE | C21: TRADE_SETTLE_DATE_MISMATCH | D21: Trade Accounting & Operation | E21: FUND_ALPHA | F21: SEC022 | G21: TRD100076 | H21: 2026-10-01 | I21: 2026-10-02 | K21: 1353702.4 | L21: 46296 | M21: 4 | N21: 2-5d | O21: HIGH | P21: Settlement dates disagree; risk of a settlement fail. | Q21: Check SSI and settlement instructions; align settle date to avoid a fail.
A22: BRK-20261007-0021 | B22: TRADE | C22: TRADE_SETTLE_DATE_MISMATCH | D22: Trade Accounting & Operation | E22: FUND_ALPHA | F22: SEC012 | G22: TRD100157 | H22: 2026-09-28 | I22: 2026-09-29 | K22: 759163.03 | L22: 46293 | M22: 7 | N22: 6-10d | O22: HIGH | P22: Settlement dates disagree; risk of a settlement fail. | Q22: Check SSI and settlement instructions; align settle date to avoid a fail.
A23: BRK-20261007-0022 | B23: CASH | C23: CASH_BREAK_UPSTREAM_DRIVEN | D23: Trade Accounting & Operation | E23: FUND_GAMMA | G23: FUND_GAMMA|USD | H23: -38465221 | I23: -37885827 | J23: -579394.31 | K23: 579394.31 | L23: 46302 | M23: 0 | N23: 0-1d | O23: HIGH | P23: Fully explained by: trade breaks -532,021.12; margin breaks -42,558.19; unbooked dividends -4,815.00; residual -0.00 | Q23: No separate action; clears when linked trade, margin and corporate action breaks clear.
A24: BRK-20261007-0023 | B24: TRADE | C24: TRADE_MISSING_IN_INTERNAL | D24: Trade Accounting & Operation | E24: FUND_GAMMA | F24: SEC018 | G24: TRD90000 | H24: (missing) | I24: SELL 2,100 @ 226.0664 | K24: 474739.44 | L24: 46289 | M24: 9 | N24: 6-10d | O24: MEDIUM | P24: Trade exists at the custodian but not on the platform. | Q24: Check for unbooked trade or wrong account; book trade or reject with custodian.
A25: BRK-20261007-0024 | B25: POSITION | C25: POSITION_BREAK_TRADE_DRIVEN | D25: Trade Accounting & Operation | E25: FUND_GAMMA | F25: SEC018 | G25: FUND_GAMMA|SEC018 | H25: 40400 | I25: 38300 | J25: 2100 | K25: 474724.74 | L25: 46302 | M25: 0 | N25: 0-1d | O25: MEDIUM | P25: Fully explained by trade break(s): TRD90000 | Q25: No separate action; clears when the linked trade break is resolved.
A26: BRK-20261007-0025 | B26: TRADE | C26: TRADE_MISSING_IN_INTERNAL | D26: Trade Accounting & Operation | E26: FUND_ALPHA | F26: SEC019 | G26: TRD90002 | H26: (missing) | I26: BUY 3,600 @ 101.9549 | K26: 367037.64 | L26: 46297 | M26: 3 | N26: 2-5d | O26: MEDIUM | P26: Trade exists at the custodian but not on the platform. | Q26: Check for unbooked trade or wrong account; book trade or reject with custodian.
A27: BRK-20261007-0026 | B27: POSITION | C27: POSITION_BREAK_TRADE_DRIVEN | D27: Trade Accounting & Operation | E27: FUND_ALPHA | F27: SEC019 | G27: FUND_ALPHA|SEC019 | H27: 68000 | I27: 71500 | J27: -3500 | K27: 356841.45 | L27: 46302 | M27: 0 | N27: 0-1d | O27: MEDIUM | P27: Fully explained by trade break(s): TRD100230, TRD100284, TRD90002 | Q27: No separate action; clears when the linked trade break is resolved.
A28: BRK-20261007-0027 | B28: PRICING | C28: PRICING_VARIANCE | D28: Pricing | F28: SEC021 | G28: SEC021 | H28: 97.1958 | I28: 95.4449 | J28: 1.7509 | K28: 226216.28 | L28: 46302 | M28: 0 | N28: 0-1d | O28: MEDIUM | P28: Platform vs street differs by +183.4 bps (tolerance 25 bps, FIXED_INCOME). | Q28: Compare vendor and street source; challenge or override with documented support.
A29: BRK-20261007-0028 | B29: PRICING | C29: PRICING_VARIANCE | D29: Pricing | F29: SEC002 | G29: SEC002 | H29: 346.8085 | I29: 351.109 | J29: -4.3005 | K29: 218035.35 | L29: 46302 | M29: 0 | N29: 0-1d | O29: MEDIUM | P29: Platform vs street differs by -122.5 bps (tolerance 10 bps, EQUITY). | Q29: Compare vendor and street source; challenge or override with documented support.
A30: BRK-20261007-0029 | B30: TRADE | C30: TRADE_MISSING_IN_INTERNAL | D30: Trade Accounting & Operation | E30: FUND_BETA | F30: SEC005 | G30: TRD90003 | H30: (missing) | I30: SELL 3,400 @ 42.5156 | K30: 144553.04 | L30: 46290 | M30: 8 | N30: 6-10d | O30: MEDIUM | P30: Trade exists at the custodian but not on the platform. | Q30: Check for unbooked trade or wrong account; book trade or reject with custodian.
A31: BRK-20261007-0030 | B31: POSITION | C31: POSITION_BREAK_TRADE_DRIVEN | D31: Trade Accounting & Operation | E31: FUND_BETA | F31: SEC005 | G31: FUND_BETA|SEC005 | H31: 9600 | I31: 6200 | J31: 3400 | K31: 144544.2 | L31: 46302 | M31: 0 | N31: 0-1d | O31: MEDIUM | P31: Fully explained by trade break(s): TRD90003 | Q31: No separate action; clears when the linked trade break is resolved.
A32: BRK-20261007-0031 | B32: PRICING | C32: PRICING_STALE | D32: Pricing | F32: SEC016 | G32: SEC016 | H32: 80.8847 | I32: 82.3837 | J32: -1.499 | K32: 131912 | L32: 46302 | M32: 0 | N32: 0-1d | O32: MEDIUM | P32: Platform price equals prior-day price; street moved 185 bps. | Q32: Price not refreshed since prior day; re-pull the price feed and revalue.
A33: BRK-20261007-0032 | B33: TRADE | C33: TRADE_PRICE_MISMATCH | D33: Trade Accounting & Operation | E33: FUND_ALPHA | F33: SEC011 | G33: TRD100089 | H33: 393.472 | I33: 386.8956 | J33: 6.5764 | K33: 129555.08 | L33: 46289 | M33: 9 | N33: 6-10d | O33: MEDIUM | P33: Price differs by 170.0 bps (tolerance 1.0 bps). | Q33: Obtain broker confirm; correct price and book the P&L / cash adjustment.
A34: BRK-20261007-0033 | B34: MARGIN | C34: MARGIN_MISSING_IN_INTERNAL | D34: Treasury | E34: FUND_GAMMA | G34: MRG9001 | H34: (missing) | I34: 120000 | K34: 120000 | L34: 46302 | M34: 0 | N34: 0-1d | O34: MEDIUM | P34: Margin movement with Harbor Prime not booked on the platform. | Q34: Confirm margin call received; book the movement if valid.
A35: BRK-20261007-0034 | B35: TRADE | C35: TRADE_MISSING_IN_CUSTODIAN | D35: Trade Accounting & Operation | E35: FUND_BETA | F35: SEC003 | G35: TRD100042 | H35: BUY 700 @ 156.8701 | I35: (missing) | K35: 109809.07 | L35: 46297 | M35: 3 | N35: 2-5d | O35: MEDIUM | P35: Trade exists on the platform but not at the custodian. | Q35: Confirm trade with counterparty; check allocation and send trade to custodian.
A36: BRK-20261007-0035 | B36: TRADE | C36: TRADE_QTY_MISMATCH | D36: Trade Accounting & Operation | E36: FUND_BETA | F36: SEC020 | G36: TRD100083 | H36: 4000 | I36: 3100 | J36: 900 | K36: 96886.71 | L36: 46294 | M36: 6 | N36: 6-10d | O36: MEDIUM | P36: Quantity differs by 900. | Q36: Obtain broker confirm; correct quantity on the side that disagrees.
A37: BRK-20261007-0036 | B37: TRADE | C37: TRADE_PRICE_MISMATCH | D37: Trade Accounting & Operation | E37: FUND_ALPHA | F37: SEC012 | G37: TRD100056 | H37: 242.8528 | I37: 238.0794 | J37: 4.7734 | K37: 84966.52 | L37: 46302 | M37: 0 | N37: 0-1d | O37: MEDIUM | P37: Price differs by 200.5 bps (tolerance 1.0 bps). | Q37: Obtain broker confirm; correct price and book the P&L / cash adjustment.
A38: BRK-20261007-0037 | B38: TRADE | C38: TRADE_QTY_MISMATCH | D38: Trade Accounting & Operation | E38: FUND_BETA | F38: SEC003 | G38: TRD100166 | H38: 16100 | I38: 15600 | J38: 500 | K38: 79324.65 | L38: 46302 | M38: 0 | N38: 0-1d | O38: MEDIUM | P38: Quantity differs by 500. | Q38: Obtain broker confirm; correct quantity on the side that disagrees.
A39: BRK-20261007-0038 | B39: MARGIN | C39: MARGIN_MISSING_IN_CUSTODIAN | D39: Treasury | E39: FUND_GAMMA | G39: MRG1000 | H39: 77441.81 | I39: (missing) | K39: 77441.81 | L39: 46296 | M39: 4 | N39: 2-5d | O39: MEDIUM | P39: Margin movement with Atlas Markets not found at the custodian. | Q39: Confirm margin call with counterparty; check whether the movement was sent or settled.
A40: BRK-20261007-0039 | B40: POSITION | C40: POSITION_BREAK_TRADE_DRIVEN | D40: Trade Accounting & Operation | E40: FUND_BETA | F40: SEC020 | G40: FUND_BETA|SEC020 | H40: -21100 | I40: -20500 | J40: -600 | K40: 64694.1 | L40: 46302 | M40: 0 | N40: 0-1d | O40: MEDIUM | P40: Fully explained by trade break(s): TRD100083, TRD100153 | Q40: No separate action; clears when the linked trade break is resolved.
...

Sheet Trade Breaks
A1: Break Id | B1: Category | C1: Break Type | D1: Owner Team | E1: Account | F1: Security Id | G1: Reference | H1: Internal Value | I1: Custodian Value | J1: Difference | K1: Notional Usd | L1: Reference Date | M1: Age Days | N1: Age Bucket | O1: Severity | P1: Explanation | Q1: Suggested Action
A2: BRK-20261007-0007 | B2: TRADE | C2: TRADE_SETTLE_DATE_MISMATCH | D2: Trade Accounting & Operation | E2: FUND_ALPHA | F2: SEC012 | G2: TRD100187 | H2: 2026-10-06 | I2: 2026-10-07 | K2: 4821861.5 | L2: 46301 | M2: 1 | N2: 0-1d | O2: HIGH | P2: Settlement dates disagree; risk of a settlement fail. | Q2: Check SSI and settlement instructions; align settle date to avoid a fail.
A3: BRK-20261007-0008 | B3: TRADE | C3: TRADE_MISSING_IN_CUSTODIAN | D3: Trade Accounting & Operation | E3: FUND_ALPHA | F3: SEC011 | G3: TRD100267 | H3: SELL 11,800 @ 391.9323 | I3: (missing) | K3: 4624801.1 | L3: 46300 | M3: 2 | N3: 2-5d | O3: HIGH | P3: Trade exists on the platform but not at the custodian. | Q3: Confirm trade with counterparty; check allocation and send trade to custodian.
A4: BRK-20261007-0009 | B4: TRADE | C4: TRADE_SETTLE_DATE_MISMATCH | D4: Trade Accounting & Operation | E4: FUND_BETA | F4: SEC012 | G4: TRD100046 | H4: 2026-10-06 | I4: 2026-10-07 | K4: 3714541 | L4: 46301 | M4: 1 | N4: 0-1d | O4: HIGH | P4: Settlement dates disagree; risk of a settlement fail. | Q4: Check SSI and settlement instructions; align settle date to avoid a fail.
A5: BRK-20261007-0011 | B5: TRADE | C5: TRADE_MISSING_IN_CUSTODIAN | D5: Trade Accounting & Operation | E5: FUND_BETA | F5: SEC015 | G5: TRD100164 | H5: BUY 13,500 @ 216.9081 | I5: (missing) | K5: 2928259.4 | L5: 46290 | M5: 8 | N5: 6-10d | O5: HIGH | P5: Trade exists on the platform but not at the custodian. | Q5: Confirm trade with counterparty; check allocation and send trade to custodian.
A6: BRK-20261007-0014 | B6: TRADE | C6: TRADE_MISSING_IN_CUSTODIAN | D6: Trade Accounting & Operation | E6: FUND_BETA | F6: SEC018 | G6: TRD100292 | H6: BUY 12,700 @ 224.9186 | I6: (missing) | K6: 2856466.2 | L6: 46296 | M6: 4 | N6: 2-5d | O6: HIGH | P6: Trade exists on the platform but not at the custodian. | Q6: Confirm trade with counterparty; check allocation and send trade to custodian.
A7: BRK-20261007-0015 | B7: TRADE | C7: TRADE_SETTLE_DATE_MISMATCH | D7: Trade Accounting & Operation | E7: FUND_GAMMA | F7: SEC007 | G7: TRD100091 | H7: 2026-09-25 | I7: 2026-09-28 | K7: 2070628.4 | L7: 46290 | M7: 8 | N7: 6-10d | O7: HIGH | P7: Settlement dates disagree; risk of a settlement fail. | Q7: Check SSI and settlement instructions; align settle date to avoid a fail.
A8: BRK-20261007-0018 | B8: TRADE | C8: TRADE_MISSING_IN_CUSTODIAN | D8: Trade Accounting & Operation | E8: FUND_ALPHA | F8: SEC008 | G8: TRD100027 | H8: BUY 19,500 @ 76.9914 | I8: (missing) | K8: 1501332.3 | L8: 46289 | M8: 9 | N8: 6-10d | O8: HIGH | P8: Trade exists on the platform but not at the custodian. | Q8: Confirm trade with counterparty; check allocation and send trade to custodian.
A9: BRK-20261007-0019 | B9: TRADE | C9: TRADE_MISSING_IN_INTERNAL | D9: Trade Accounting & Operation | E9: FUND_ALPHA | F9: SEC011 | G9: TRD90001 | H9: (missing) | I9: SELL 3,800 @ 391.9242 | K9: 1489312 | L9: 46288 | M9: 10 | N9: 6-10d | O9: HIGH | P9: Trade exists at the custodian but not on the platform. | Q9: Check for unbooked trade or wrong account; book trade or reject with custodian.
A10: BRK-20261007-0020 | B10: TRADE | C10: TRADE_SETTLE_DATE_MISMATCH | D10: Trade Accounting & Operation | E10: FUND_ALPHA | F10: SEC022 | G10: TRD100076 | H10: 2026-10-01 | I10: 2026-10-02 | K10: 1353702.4 | L10: 46296 | M10: 4 | N10: 2-5d | O10: HIGH | P10: Settlement dates disagree; risk of a settlement fail. | Q10: Check SSI and settlement instructions; align settle date to avoid a fail.
A11: BRK-20261007-0021 | B11: TRADE | C11: TRADE_SETTLE_DATE_MISMATCH | D11: Trade Accounting & Operation | E11: FUND_ALPHA | F11: SEC012 | G11: TRD100157 | H11: 2026-09-28 | I11: 2026-09-29 | K11: 759163.03 | L11: 46293 | M11: 7 | N11: 6-10d | O11: HIGH | P11: Settlement dates disagree; risk of a settlement fail. | Q11: Check SSI and settlement instructions; align settle date to avoid a fail.
A12: BRK-20261007-0023 | B12: TRADE | C12: TRADE_MISSING_IN_INTERNAL | D12: Trade Accounting & Operation | E12: FUND_GAMMA | F12: SEC018 | G12: TRD90000 | H12: (missing) | I12: SELL 2,100 @ 226.0664 | K12: 474739.44 | L12: 46289 | M12: 9 | N12: 6-10d | O12: MEDIUM | P12: Trade exists at the custodian but not on the platform. | Q12: Check for unbooked trade or wrong account; book trade or reject with custodian.
A13: BRK-20261007-0025 | B13: TRADE | C13: TRADE_MISSING_IN_INTERNAL | D13: Trade Accounting & Operation | E13: FUND_ALPHA | F13: SEC019 | G13: TRD90002 | H13: (missing) | I13: BUY 3,600 @ 101.9549 | K13: 367037.64 | L13: 46297 | M13: 3 | N13: 2-5d | O13: MEDIUM | P13: Trade exists at the custodian but not on the platform. | Q13: Check for unbooked trade or wrong account; book trade or reject with custodian.
A14: BRK-20261007-0029 | B14: TRADE | C14: TRADE_MISSING_IN_INTERNAL | D14: Trade Accounting & Operation | E14: FUND_BETA | F14: SEC005 | G14: TRD90003 | H14: (missing) | I14: SELL 3,400 @ 42.5156 | K14: 144553.04 | L14: 46290 | M14: 8 | N14: 6-10d | O14: MEDIUM | P14: Trade exists at the custodian but not on the platform. | Q14: Check for unbooked trade or wrong account; book trade or reject with custodian.
A15: BRK-20261007-0032 | B15: TRADE | C15: TRADE_PRICE_MISMATCH | D15: Trade Accounting & Operation | E15: FUND_ALPHA | F15: SEC011 | G15: TRD100089 | H15: 393.472 | I15: 386.8956 | J15: 6.5764 | K15: 129555.08 | L15: 46289 | M15: 9 | N15: 6-10d | O15: MEDIUM | P15: Price differs by 170.0 bps (tolerance 1.0 bps). | Q15: Obtain broker confirm; correct price and book the P&L / cash adjustment.
A16: BRK-20261007-0034 | B16: TRADE | C16: TRADE_MISSING_IN_CUSTODIAN | D16: Trade Accounting & Operation | E16: FUND_BETA | F16: SEC003 | G16: TRD100042 | H16: BUY 700 @ 156.8701 | I16: (missing) | K16: 109809.07 | L16: 46297 | M16: 3 | N16: 2-5d | O16: MEDIUM | P16: Trade exists on the platform but not at the custodian. | Q16: Confirm trade with counterparty; check allocation and send trade to custodian.
A17: BRK-20261007-0035 | B17: TRADE | C17: TRADE_QTY_MISMATCH | D17: Trade Accounting & Operation | E17: FUND_BETA | F17: SEC020 | G17: TRD100083 | H17: 4000 | I17: 3100 | J17: 900 | K17: 96886.71 | L17: 46294 | M17: 6 | N17: 6-10d | O17: MEDIUM | P17: Quantity differs by 900. | Q17: Obtain broker confirm; correct quantity on the side that disagrees.
A18: BRK-20261007-0036 | B18: TRADE | C18: TRADE_PRICE_MISMATCH | D18: Trade Accounting & Operation | E18: FUND_ALPHA | F18: SEC012 | G18: TRD100056 | H18: 242.8528 | I18: 238.0794 | J18: 4.7734 | K18: 84966.52 | L18: 46302 | M18: 0 | N18: 0-1d | O18: MEDIUM | P18: Price differs by 200.5 bps (tolerance 1.0 bps). | Q18: Obtain broker confirm; correct price and book the P&L / cash adjustment.
A19: BRK-20261007-0037 | B19: TRADE | C19: TRADE_QTY_MISMATCH | D19: Trade Accounting & Operation | E19: FUND_BETA | F19: SEC003 | G19: TRD100166 | H19: 16100 | I19: 15600 | J19: 500 | K19: 79324.65 | L19: 46302 | M19: 0 | N19: 0-1d | O19: MEDIUM | P19: Quantity differs by 500. | Q19: Obtain broker confirm; correct quantity on the side that disagrees.
A20: BRK-20261007-0040 | B20: TRADE | C20: TRADE_MISSING_IN_CUSTODIAN | D20: Trade Accounting & Operation | E20: FUND_ALPHA | F20: SEC019 | G20: TRD100284 | H20: BUY 600 @ 102.1778 | I20: (missing) | K20: 61306.68 | L20: 46302 | M20: 0 | N20: 0-1d | O20: MEDIUM | P20: Trade exists on the platform but not at the custodian. | Q20: Confirm trade with counterparty; check allocation and send trade to custodian.
A21: BRK-20261007-0041 | B21: TRADE | C21: TRADE_QTY_MISMATCH | D21: Trade Accounting & Operation | E21: FUND_ALPHA | F21: SEC019 | G21: TRD100230 | H21: 19900 | I21: 20400 | J21: -500 | K21: 50923.3 | L21: 46300 | M21: 2 | N21: 2-5d | O21: MEDIUM | P21: Quantity differs by 500. | Q21: Obtain broker confirm; correct quantity on the side that disagrees.
A22: BRK-20261007-0042 | B22: TRADE | C22: TRADE_QTY_MISMATCH | D22: Trade Accounting & Operation | E22: FUND_BETA | F22: SEC016 | G22: TRD100058 | H22: 18400 | I22: 19000 | J22: -600 | K22: 49406.28 | L22: 46289 | M22: 9 | N22: 6-10d | O22: LOW | P22: Quantity differs by 600. | Q22: Obtain broker confirm; correct quantity on the side that disagrees.
A23: BRK-20261007-0044 | B23: TRADE | C23: TRADE_QTY_MISMATCH | D23: Trade Accounting & Operation | E23: FUND_GAMMA | F23: SEC022 | G23: TRD100262 | H23: 18600 | I23: 18200 | J23: 400 | K23: 37947.88 | L23: 46300 | M23: 2 | N23: 2-5d | O23: LOW | P23: Quantity differs by 400. | Q23: Obtain broker confirm; correct quantity on the side that disagrees.
A24: BRK-20261007-0046 | B24: TRADE | C24: TRADE_QTY_MISMATCH | D24: Trade Accounting & Operation | E24: FUND_BETA | F24: SEC020 | G24: TRD100153 | H24: 2500 | I24: 2200 | J24: 300 | K24: 32125.17 | L24: 46294 | M24: 6 | N24: 6-10d | O24: LOW | P24: Quantity differs by 300. | Q24: Obtain broker confirm; correct quantity on the side that disagrees.
A25: BRK-20261007-0048 | B25: TRADE | C25: TRADE_PRICE_MISMATCH | D25: Trade Accounting & Operation | E25: FUND_ALPHA | F25: SEC018 | G25: TRD100015 | H25: 224.776 | I25: 227.7121 | J25: -2.9361 | K25: 28480.17 | L25: 46293 | M25: 7 | N25: 6-10d | O25: LOW | P25: Price differs by 128.9 bps (tolerance 1.0 bps). | Q25: Obtain broker confirm; correct price and book the P&L / cash adjustment.
A26: BRK-20261007-0050 | B26: TRADE | C26: TRADE_QTY_MISMATCH | D26: Trade Accounting & Operation | E26: FUND_BETA | F26: SEC008 | G26: TRD100179 | H26: 10000 | I26: 10300 | J26: -300 | K26: 23075.97 | L26: 46293 | M26: 7 | N26: 6-10d | O26: LOW | P26: Quantity differs by 300. | Q26: Obtain broker confirm; correct quantity on the side that disagrees.
A27: BRK-20261007-0051 | B27: TRADE | C27: TRADE_PRICE_MISMATCH | D27: Trade Accounting & Operation | E27: FUND_ALPHA | F27: SEC002 | G27: TRD100169 | H27: 352.6565 | I27: 354.6241 | J27: -1.9676 | K27: 19872.76 | L27: 46300 | M27: 2 | N27: 2-5d | O27: LOW | P27: Price differs by 55.5 bps (tolerance 1.0 bps). | Q27: Obtain broker confirm; correct price and book the P&L / cash adjustment.
A28: BRK-20261007-0052 | B28: TRADE | C28: TRADE_PRICE_MISMATCH | D28: Trade Accounting & Operation | E28: FUND_GAMMA | F28: SEC017 | G28: TRD100276 | H28: 103.547 | I28: 102.4729 | J28: 1.0741 | K28: 19333.8 | L28: 46300 | M28: 2 | N28: 2-5d | O28: LOW | P28: Price differs by 104.8 bps (tolerance 1.0 bps). | Q28: Obtain broker confirm; correct price and book the P&L / cash adjustment.
A29: BRK-20261007-0053 | B29: TRADE | C29: TRADE_PRICE_MISMATCH | D29: Trade Accounting & Operation | E29: FUND_ALPHA | F29: SEC015 | G29: TRD100205 | H29: 215.7184 | I29: 214.5996 | J29: 1.1188 | K29: 19243.36 | L29: 46293 | M29: 7 | N29: 6-10d | O29: LOW | P29: Price differs by 52.1 bps (tolerance 1.0 bps). | Q29: Obtain broker confirm; correct price and book the P&L / cash adjustment.
A30: BRK-20261007-0055 | B30: TRADE | C30: TRADE_PRICE_MISMATCH | D30: Trade Accounting & Operation | E30: FUND_BETA | F30: SEC022 | G30: TRD100297 | H30: 94.445 | I30: 93.4577 | J30: 0.9873 | K30: 14217.12 | L30: 46293 | M30: 7 | N30: 6-10d | O30: LOW | P30: Price differs by 105.6 bps (tolerance 1.0 bps). | Q30: Obtain broker confirm; correct price and book the P&L / cash adjustment.
A31: BRK-20261007-0058 | B31: TRADE | C31: TRADE_QTY_MISMATCH | D31: Trade Accounting & Operation | E31: FUND_ALPHA | F31: SEC022 | G31: TRD100131 | H31: 4400 | I31: 4300 | J31: 100 | K31: 9425.03 | L31: 46302 | M31: 0 | N31: 0-1d | O31: LOW | P31: Quantity differs by 100. | Q31: Obtain broker confirm; correct quantity on the side that disagrees.
A32: BRK-20261007-0060 | B32: TRADE | C32: TRADE_PRICE_MISMATCH | D32: Trade Accounting & Operation | E32: FUND_ALPHA | F32: SEC022 | G32: TRD100248 | H32: 95.1973 | I32: 94.0756 | J32: 1.1217 | K32: 897.36 | L32: 46301 | M32: 1 | N32: 0-1d | O32: LOW | P32: Price differs by 119.2 bps (tolerance 1.0 bps). | Q32: Obtain broker confirm; correct price and book the P&L / cash adjustment.

Sheet Position Breaks
A1: Break Id | B1: Category | C1: Break Type | D1: Owner Team | E1: Account | F1: Security Id | G1: Reference | H1: Internal Value | I1: Custodian Value | J1: Difference | K1: Notional Usd | L1: Reference Date | M1: Age Days | N1: Age Bucket | O1: Severity | P1: Explanation | Q1: Suggested Action
A2: BRK-20261007-0001 | B2: POSITION | C2: POSITION_BREAK_CORP_ACTION_SPLIT | D2: Middle Office | E2: FUND_GAMMA | F2: SEC009 | G2: FUND_GAMMA|SEC009 | H2: 37000 | I2: 74000 | J2: -37000 | K2: 12218536 | L2: 46302 | M2: 0 | N2: 0-1d | O2: HIGH | P2: Custodian quantity is exactly 2x the platform: 2-for-1 split not booked on the platform. | Q2: Book the split on the platform (ratio and ex-date) and re-run.
A3: BRK-20261007-0002 | B3: POSITION | C3: POSITION_BREAK_CORP_ACTION_SPLIT | D3: Middle Office | E3: FUND_ALPHA | F3: SEC009 | G3: FUND_ALPHA|SEC009 | H3: 31600 | I3: 63200 | J3: -31600 | K3: 10435290 | L3: 46302 | M3: 0 | N3: 0-1d | O3: HIGH | P3: Custodian quantity is exactly 2x the platform: 2-for-1 split not booked on the platform. | Q3: Book the split on the platform (ratio and ex-date) and re-run.
A4: BRK-20261007-0003 | B4: POSITION | C4: POSITION_BREAK_CORP_ACTION_SPLIT | D4: Middle Office | E4: FUND_BETA | F4: SEC009 | G4: FUND_BETA|SEC009 | H4: -25600 | I4: -51200 | J4: 25600 | K4: 8453905.9 | L4: 46302 | M4: 0 | N4: 0-1d | O4: HIGH | P4: Custodian quantity is exactly 2x the platform: 2-for-1 split not booked on the platform. | Q4: Book the split on the platform (ratio and ex-date) and re-run.
A5: BRK-20261007-0004 | B5: POSITION | C5: POSITION_BREAK_CORP_ACTION_SPLIT | D5: Middle Office | E5: FUND_GAMMA | F5: SEC004 | G5: FUND_GAMMA|SEC004 | H5: 33000 | I5: 66000 | J5: -33000 | K5: 8160814.2 | L5: 46302 | M5: 0 | N5: 0-1d | O5: HIGH | P5: Custodian quantity is exactly 2x the platform: 2-for-1 split not booked on the platform. | Q5: Book the split on the platform (ratio and ex-date) and re-run.
A6: BRK-20261007-0005 | B6: POSITION | C6: POSITION_BREAK_CORP_ACTION_SPLIT | D6: Middle Office | E6: FUND_ALPHA | F6: SEC004 | G6: FUND_ALPHA|SEC004 | H6: 28900 | I6: 57800 | J6: -28900 | K6: 7146894.9 | L6: 46302 | M6: 0 | N6: 0-1d | O6: HIGH | P6: Custodian quantity is exactly 2x the platform: 2-for-1 split not booked on the platform. | Q6: Book the split on the platform (ratio and ex-date) and re-run.
A7: BRK-20261007-0006 | B7: POSITION | C7: POSITION_BREAK_CORP_ACTION_SPLIT | D7: Middle Office | E7: FUND_BETA | F7: SEC004 | G7: FUND_BETA|SEC004 | H7: -26700 | I7: -53400 | J7: 26700 | K7: 6602840.6 | L7: 46302 | M7: 0 | N7: 0-1d | O7: HIGH | P7: Custodian quantity is exactly 2x the platform: 2-for-1 split not booked on the platform. | Q7: Book the split on the platform (ratio and ex-date) and re-run.
A8: BRK-20261007-0010 | B8: POSITION | C8: POSITION_BREAK_TRADE_DRIVEN | D8: Trade Accounting & Operation | E8: FUND_ALPHA | F8: SEC011 | G8: FUND_ALPHA|SEC011 | H8: 39600 | I8: 47600 | J8: -8000 | K8: 3135335.2 | L8: 46302 | M8: 0 | N8: 0-1d | O8: HIGH | P8: Fully explained by trade break(s): TRD100089, TRD100267, TRD90001 | Q8: No separate action; clears when the linked trade break is resolved.
A9: BRK-20261007-0012 | B9: POSITION | C9: POSITION_BREAK_TRADE_DRIVEN | D9: Trade Accounting & Operation | E9: FUND_BETA | F9: SEC015 | G9: FUND_BETA|SEC015 | H9: 14500 | I9: 1000 | J9: 13500 | K9: 2916110.7 | L9: 46302 | M9: 0 | N9: 0-1d | O9: HIGH | P9: Fully explained by trade break(s): TRD100164 | Q9: No separate action; clears when the linked trade break is resolved.
A10: BRK-20261007-0013 | B10: POSITION | C10: POSITION_BREAK_TRADE_DRIVEN | D10: Trade Accounting & Operation | E10: FUND_BETA | F10: SEC018 | G10: FUND_BETA|SEC018 | H10: -300 | I10: -13000 | J10: 12700 | K10: 2870954.4 | L10: 46302 | M10: 0 | N10: 0-1d | O10: HIGH | P10: Fully explained by trade break(s): TRD100292 | Q10: No separate action; clears when the linked trade break is resolved.
A11: BRK-20261007-0017 | B11: POSITION | C11: POSITION_BREAK_TRADE_DRIVEN | D11: Trade Accounting & Operation | E11: FUND_ALPHA | F11: SEC008 | G11: FUND_ALPHA|SEC008 | H11: 22800 | I11: 3300 | J11: 19500 | K11: 1502987.9 | L11: 46302 | M11: 0 | N11: 0-1d | O11: HIGH | P11: Fully explained by trade break(s): TRD100027 | Q11: No separate action; clears when the linked trade break is resolved.
A12: BRK-20261007-0024 | B12: POSITION | C12: POSITION_BREAK_TRADE_DRIVEN | D12: Trade Accounting & Operation | E12: FUND_GAMMA | F12: SEC018 | G12: FUND_GAMMA|SEC018 | H12: 40400 | I12: 38300 | J12: 2100 | K12: 474724.74 | L12: 46302 | M12: 0 | N12: 0-1d | O12: MEDIUM | P12: Fully explained by trade break(s): TRD90000 | Q12: No separate action; clears when the linked trade break is resolved.
A13: BRK-20261007-0026 | B13: POSITION | C13: POSITION_BREAK_TRADE_DRIVEN | D13: Trade Accounting & Operation | E13: FUND_ALPHA | F13: SEC019 | G13: FUND_ALPHA|SEC019 | H13: 68000 | I13: 71500 | J13: -3500 | K13: 356841.45 | L13: 46302 | M13: 0 | N13: 0-1d | O13: MEDIUM | P13: Fully explained by trade break(s): TRD100230, TRD100284, TRD90002 | Q13: No separate action; clears when the linked trade break is resolved.
... A20: BRK-20261007-0057 | B20: POSITION | C20: POSITION_BREAK_TRADE_DRIVEN | D20: Trade Accounting & Operation | E20: FUND_ALPHA | F20: SEC022 | G20: FUND_ALPHA|SEC022 | H20: -23500 | I20: -23400 | J20: -100 | K20: 9456.41 | L20: 46302 | M20: 0 | N20: 0-1d | O20: LOW | P20: Fully explained by trade break(s): TRD100076, TRD100131, TRD100248 | Q20: No separate action; clears when the linked trade break is resolved.

Sheet Cash Breaks
A1: Break Id | B1: Category | C1: Break Type | D1: Owner Team | E1: Account | F1: Security Id | G1: Reference | H1: Internal Value | I1: Custodian Value | J1: Difference | K1: Notional Usd | L1: Reference Date | M1: Age Days | N1: Age Bucket | O1: Severity | P1: Explanation | Q1: Suggested Action
A2: BRK-20261007-0016 | B2: CASH | C2: CASH_BREAK_UPSTREAM_DRIVEN | D2: Trade Accounting & Operation | E2: FUND_ALPHA | G2: FUND_ALPHA|USD | H2: -12494368 | I2: -14468854 | J2: 1974486.1 | K2: 1974486.1 | L2: 46302 | M2: 0 | N2: 0-1d | O2: HIGH | P2: Fully explained by: trade breaks 1,976,331.08; margin breaks 0.00; unbooked dividends -1,845.00; residual 0.00 | Q2: No separate action; clears when linked trade, margin and corporate action breaks clear.
A3: BRK-20261007-0022 | B3: CASH | C3: CASH_BREAK_UPSTREAM_DRIVEN | D3: Trade Accounting & Operation | E3: FUND_GAMMA | G3: FUND_GAMMA|USD | H3: -38465221 | I3: -37885827 | J3: -579394.31 | K3: 579394.31 | L3: 46302 | M3: 0 | N3: 0-1d | O3: HIGH | P3: Fully explained by: trade breaks -532,021.12; margin breaks -42,558.19; unbooked dividends -4,815.00; residual -0.00 | Q3: No separate action; clears when linked trade, margin and corporate action breaks clear.
A4: BRK-20261007-0061 | B4: CASH | C4: CASH_BREAK_UNEXPLAINED_RESIDUAL | D4: Trade Accounting & Operation | E4: FUND_BETA | G4: FUND_BETA|USD | H4: 67174990 | I4: 73000876 | J4: -5825885.8 | K4: 125 | L4: 46302 | M4: 0 | N4: 0-1d | O4: LOW | P4: Residual remains after known causes: trade breaks -5,808,288.99; margin breaks -17,766.78; unbooked dividends 45.00; residual 125.00 | Q4: Investigate the residual: fees, interest, FX or unbooked cash movement; book adjustment.

Sheet Margin Breaks
A1: Break Id | B1: Category | C1: Break Type | D1: Owner Team | E1: Account | F1: Security Id | G1: Reference | H1: Internal Value | I1: Custodian Value | J1: Difference | K1: Notional Usd | L1: Reference Date | M1: Age Days | N1: Age Bucket | O1: Severity | P1: Explanation | Q1: Suggested Action
A2: BRK-20261007-0033 | B2: MARGIN | C2: MARGIN_MISSING_IN_INTERNAL | D2: Treasury | E2: FUND_GAMMA | G2: MRG9001 | H2: (missing) | I2: 120000 | K2: 120000 | L2: 46302 | M2: 0 | N2: 0-1d | O2: MEDIUM | P2: Margin movement with Harbor Prime not booked on the platform. | Q2: Confirm margin call received; book the movement if valid.
A3: BRK-20261007-0038 | B3: MARGIN | C3: MARGIN_MISSING_IN_CUSTODIAN | D3: Treasury | E3: FUND_GAMMA | G3: MRG1000 | H3: 77441.81 | I3: (missing) | K3: 77441.81 | L3: 46296 | M3: 4 | N3: 2-5d | O3: MEDIUM | P3: Margin movement with Atlas Markets not found at the custodian. | Q3: Confirm margin call with counterparty; check whether the movement was sent or settled.
A4: BRK-20261007-0054 | B4: MARGIN | C4: MARGIN_AMOUNT_MISMATCH | D4: Treasury | E4: FUND_BETA | G4: MRG1001 | H4: 710651.02 | I4: 728417.3 | J4: -17766.28 | K4: 17766.28 | L4: 46301 | M4: 1 | N4: 0-1d | O4: LOW | P4: Amounts differ by 17,766.28 (tolerance 1.00). | Q4: Compare call statements; agree the exposure and rebook the correct amount.

Sheet Pricing Breaks
A1: Break Id | B1: Category | C1: Break Type | D1: Owner Team | E1: Account | F1: Security Id | G1: Reference | H1: Internal Value | I1: Custodian Value | J1: Difference | K1: Notional Usd | L1: Reference Date | M1: Age Days | N1: Age Bucket | O1: Severity | P1: Explanation | Q1: Suggested Action
A2: BRK-20261007-0027 | B2: PRICING | C2: PRICING_VARIANCE | D2: Pricing | F2: SEC021 | G2: SEC021 | H2: 97.1958 | I2: 95.4449 | J2: 1.7509 | K2: 226216.28 | L2: 46302 | M2: 0 | N2: 0-1d | O2: MEDIUM | P2: Platform vs street differs by +183.4 bps (tolerance 25 bps, FIXED_INCOME). | Q2: Compare vendor and street source; challenge or override with documented support.
A3: BRK-20261007-0028 | B3: PRICING | C3: PRICING_VARIANCE | D3: Pricing | F3: SEC002 | G3: SEC002 | H3: 346.8085 | I3: 351.109 | J3: -4.3005 | K3: 218035.35 | L3: 46302 | M3: 0 | N3: 0-1d | O3: MEDIUM | P3: Platform vs street differs by -122.5 bps (tolerance 10 bps, EQUITY). | Q3: Compare vendor and street source; challenge or override with documented support.
A4: BRK-20261007-0031 | B4: PRICING | C4: PRICING_STALE | D4: Pricing | F4: SEC016 | G4: SEC016 | H4: 80.8847 | I4: 82.3837 | J4: -1.499 | K4: 131912 | L4: 46302 | M4: 0 | N4: 0-1d | O4: MEDIUM | P4: Platform price equals prior-day price; street moved 185 bps. | Q4: Price not refreshed since prior day; re-pull the price feed and revalue.
A5: BRK-20261007-0056 | B5: PRICING | C5: PRICING_STALE | D5: Pricing | F5: SEC007 | G5: SEC007 | H5: 142.3329 | I5: 145.8706 | J5: -3.5377 | K5: 10613.1 | L5: 46302 | M5: 0 | N5: 0-1d | O5: LOW | P5: Platform price equals prior-day price; street moved 249 bps. | Q5: Price not refreshed since prior day; re-pull the price feed and revalue.
A6: BRK-20261007-0059 | B6: PRICING | C6: PRICING_VARIANCE | D6: Pricing | F6: SEC001 | G6: SEC001 | H6: 208.7611 | I6: 212.9534 | J6: -4.1923 | K6: 7965.37 | L6: 46302 | M6: 0 | N6: 0-1d | O6: LOW | P6: Platform vs street differs by -196.9 bps (tolerance 10 bps, EQUITY). | Q6: Compare vendor and street source; challenge or override with documented support.

Sheet Tolerances
A1: Tolerances and thresholds
A2: Defined in config.py; shown here so every break is auditable
A4: Rule | B4: Value
A5: Trade price tolerance (bps) | B5: 1
A6: Position quantity tolerance | B6: 0
A7: Cash tolerance (USD) | B7: 1
A8: Margin tolerance (USD) | B8: 1
A9: Pricing tolerance, EQUITY (bps) | B9: 10
A10: Pricing tolerance, ETF (bps) | B10: 5
A11: Pricing tolerance, FIXED_INCOME (bps) | B11: 25
A12: HIGH severity at notional >= | B12: 500000
A13: MEDIUM severity at notional >= | B13: 50000
